Traceback (most recent call last):
  File "/Library/Frameworks/Python.framework/Versions/3.9/lib/python3.9/site-packages/jupyter_cache/executors/utils.py", line 58, in single_nb_execution
    executenb(
  File "/Library/Frameworks/Python.framework/Versions/3.9/lib/python3.9/site-packages/nbclient/client.py", line 1117, in execute
    return NotebookClient(nb=nb, resources=resources, km=km, **kwargs).execute()
  File "/Library/Frameworks/Python.framework/Versions/3.9/lib/python3.9/site-packages/nbclient/util.py", line 78, in wrapped
    return just_run(coro(*args, **kwargs))
  File "/Library/Frameworks/Python.framework/Versions/3.9/lib/python3.9/site-packages/nbclient/util.py", line 57, in just_run
    return loop.run_until_complete(coro)
  File "/Library/Frameworks/Python.framework/Versions/3.9/lib/python3.9/asyncio/base_events.py", line 642, in run_until_complete
    return future.result()
  File "/Library/Frameworks/Python.framework/Versions/3.9/lib/python3.9/site-packages/nbclient/client.py", line 558, in async_execute
    await self.async_execute_cell(
  File "/Library/Frameworks/Python.framework/Versions/3.9/lib/python3.9/site-packages/nbclient/client.py", line 862, in async_execute_cell
    self._check_raise_for_error(cell, exec_reply)
  File "/Library/Frameworks/Python.framework/Versions/3.9/lib/python3.9/site-packages/nbclient/client.py", line 765, in _check_raise_for_error
    raise CellExecutionError.from_cell_and_msg(cell, exec_reply_content)
nbclient.exceptions.CellExecutionError: An error occurred while executing the following cell:
------------------
# example to show tuple is immutable
my_tuple = (1, 2, 3)
print("Original tuple:", my_tuple)

# we try to change the element at index 1, the second element, in the tuple
# the error message shows we cannot change elements in tuple
my_tuple[1] = 10
print("Updated tuple:", my_tuple) # an Error is expected when run this code
------------------

[0;31m---------------------------------------------------------------------------[0m
[0;31mTypeError[0m                                 Traceback (most recent call last)
[0;32m/var/folders/qt/qy37fy6s3c1553y2k74063pr0000gn/T/ipykernel_77594/4002316466.py[0m in [0;36m<module>[0;34m[0m
[1;32m      5[0m [0;31m# we try to change the element at index 1, the second element, in the tuple[0m[0;34m[0m[0;34m[0m[0;34m[0m[0m
[1;32m      6[0m [0;31m# the error message shows we cannot change elements in tuple[0m[0;34m[0m[0;34m[0m[0;34m[0m[0m
[0;32m----> 7[0;31m [0mmy_tuple[0m[0;34m[[0m[0;36m1[0m[0;34m][0m [0;34m=[0m [0;36m10[0m[0;34m[0m[0;34m[0m[0m
[0m[1;32m      8[0m [0mprint[0m[0;34m([0m[0;34m"Updated tuple:"[0m[0;34m,[0m [0mmy_tuple[0m[0;34m)[0m [0;31m# an Error is expected when run this code[0m[0;34m[0m[0;34m[0m[0m

[0;31mTypeError[0m: 'tuple' object does not support item assignment
TypeError: 'tuple' object does not support item assignment

